Workbook

Sheet Hoja1
A1: ACID PAK 4 WAY WS 2X - ACIDIFICANTES AVICULTURA - ÁCIDO CÍTRICO, ÁCIDO SÓRBICO, STREPTOCOCCUS FAECIUM, CITRATO DE SODIO, CLORETO DE SODIO, SULFATO DE MANGANESO, CLORETO DE POTASIO, DEXTROSA, STREPTOCOCCUS FAECIUM, LACTOBACILLUS ACIDOPHILUS, ASPERGILLUS NIGER, BACILLUS SUBTILIS, BETAGLUCAN - BOLSA - 1 KG
A2: ACRILÁN - ANTISEPTICOS Y CICATRIZANTES - ACRIFLAVINA - TUBO - 50 GR
A3: AGRILAC PLUS - ALIMENTO MEDICADO GANADERIA - PRODUCTOS LÁCTEOS, ACEITES VEGETALES, OXITETRACICLINA, SULFATO DE NEOMICINA, ACEITES ORGÁNICOS, PREMEZCLA VITAMINAS, PREMEZCLA MINERALES, BHT, SABORIZANTE VAINILLA - SACO - 20 KG
A4: ALCON BROILER FINAL COSTA GRANJA - ALIMENTO BALANCEADO AVES - SUBPRODUCTOS DE MAÍZ, SOYA Y TRIGO, ACEITE VEGETAL, AMINOÁCIDOS, PREMIX VITAMINICO MINERAL, ADITIVOS FUNCIONALES, CARBONATO DE CALCIO, HIDROLIZADO MARINO, FOSFATO CÁLCICO - SACO - 40 KG
A5: ALCON BROILER FINAL SIERRA - ALIMENTO BALANCEADO AVES - SUBPRODUCTOS DE MAÍZ, SOYA Y TRIGO, ACEITE VEGETAL, AMINOÁCIDOS, PREMIX VITAMINICO MINERAL, ADITIVOS FUNCIONALES, CARBONATO DE CALCIO, HIDROLIZADO MARINO, FOSFATO CÁLCICO - SACO - 40 KG
A6: ALCON BROILER INICIAL COSTA GRANJA - ALIMENTO BALANCEADO AVES - SUBPRODUCTOS DE MAÍZ, SOYA Y TRIGO, ACEITE VEGETAL, AMINOÁCIDOS, PREMIX VITAMINICO MINERAL, ADITIVOS FUNCIONALES, CARBONATO DE CALCIO, HIDROLIZADO MARINO, FOSFATO CÁLCICO - SACO - 40 KG
A7: ALCON BROILER INICIAL SIERRA - ALIMENTO BALANCEADO AVES - SUBPRODUCTOS DE MAÍZ, SOYA Y TRIGO, ACEITE VEGETAL, AMINOÁCIDOS, PREMIX VITAMINICO MINERAL, ADITIVOS FUNCIONALES, CARBONATO DE CALCIO, HIDROLIZADO MARINO, FOSFATO CÁLCICO - SACO - 40 KG
A8: ALCON BROILER PREINICIAL COSTA GRANJA - ALIMENTO BALANCEADO AVES - SUBPRODUCTOS DE MAÍZ, SOYA Y TRIGO, ACEITE VEGETAL, AMINOÁCIDOS, PREMIX VITAMINICO MINERAL, ADITIVOS FUNCIONALES, CARBONATO DE CALCIO, HIDROLIZADO MARINO - SACO - 40 KG
A9: ALCON CERDA GESTACIÓN - ALIMENTO MEDICADO GANADERIA - SUBPRODUCTOS DE TRIGO, MAÍZ Y SOYA, HARINAS DE AFRECHO, CARBONATO CALCIO, BICARBONATO DE SODIO, AMINOÁCIDOS, ADITIVOS FUNCIONALES, ACIDIFICANTE, PREMIX VITAMÍNICO MINERAL, CLORURO DE COLINA Y SODIO, PROMOTORES DE CRECIMIENTO, ACEITE VEGETAL - SACO - 40 KG
A10: ALCON CERDA LACTANTE - ALIMENTO MEDICADO GANADERIA - SUBPRODUCTOS DE MAÍZ, TRIGO Y SOYA, HARINAS DE AFRECHO, MELAZA, ACEITE VEGETAL, BICARBONATO DE SODIO, AMINOÁCIDOS, ACIDIFICANTE, ADITIVOS FUNCIONALES, SAL, PREMIX VITAMÍNICO MINERAL, CLORURO DE COLINA, ANTIOXIDANTE, ENZIMA, PROMOTORES DE CRECIMIENTO - SACO - 40 KG
A11: ALCON CERDO ACABADO - ALIMENTO MEDICADO GANADERIA - SUBPRODUCTOS DE MAÍZ, TRIGO Y SOYA, HARINAS DE AFRECHO, ACEITE VEGETAL, BICARBONATO DE SODIO, ACIDIFICANTE, ADITIVOS FUNCIONALES, PREMIX VITAMÍNICO MINERAL, CLORURO DE SODIO Y COLINA, ANTIOXIDANTES, ENZIMAS, PROMOTORES DE CRECIMIENTO - SACO - 40 KG
A12: ALCON CERDO CRECIMIENTO - ALIMENTO MEDICADO GANADERIA - SUBPRODUCTOS DE MAÍZ, TRIGO Y SOYA, HARINAS DE AFRECHO, ACEITE VEGETAL, BICARBONATO DE SODIO, ACIDIFICANTE, AMINOÁCIDOS, ADITIVOS FUNCIONALES, PREMIX VITAMÍNICO MINERAL, CLORURO DE COLINA Y SODIO, ANTIOXIDANTES, ENZIMAS, PROMOTORES DE CRECIMIENTO - SACO - 40 KG
... A920: Detalles: DIAGEL - PRO Y PREBIÓTICO - CAJA [IMVAB_PAGINA2 | PDF]
A921: 1 | B921: Detalles: DIAGEL - ANTIDIARREICO - ELECTROLITOS, DEXTROSA, MAGNESIO [IMVAB_PAGINA3 | PDF]
A922: 2 | B922: Detalles: DOGGIMEL - NUTRICIONAL - AMINOÁCIDOS, VITAMINAS, MINERALES [IMVAB_PAGINA3 | PDF]
A923: 3 | B923: Detalles: DOGGIMEL - MISMA COMPOSICIÓN - 400 GR [IMVAB_PAGINA3 | PDF]
A924: 4 | B924: Detalles: EASOTIC - ANTIBIÓTICO + ANTIINFLAMATORIO - HIDROCORTISONA, MICONAZOL, GENTAMICINA [IMVAB_PAGINA3 | PDF]
A925: 55–58. Detalles: EFFI-RAT (raticida) - BRODIFACOUM (varias presentaciones) [IMVAB_PAGINA3 | PDF]
A926: 1 | B926: Detalles: EFFIPRO BOVIS - ANTIPARASITARIO - FIPRONIL [IMVAB_PAGINA3 | PDF]
A927: 60–63. Detalles: EFFIPRO DUO - PIPETAS - FIPRONIL + PIRIPROXIFEN [IMVAB_PAGINA3 | PDF]
A928: 1 | B928: Detalles: ELITEFLEX FORTE DOG - CONDROPROTECTOR - OMEGA 3, GLUCOSAMINA [IMVAB_PAGINA3 | PDF]
A929: 65–73. Detalles: ENDOGARD / ENDOGAR - ANTIPARASITARIOS - IVERMECTINA, PIRANTEL, FEBANTEL, PRAZIQUANTEL [IMVAB_PAGINA3 | PDF]
A930: 1 | B930: Detalles: EPIOTIC - LIMPIADOR ÓTICO - ÁCIDO SALICÍLICO, ÁCIDO LÁCTICO [IMVAB_PAGINA3 | PDF]
A931: 2 | B931: Detalles: EVACIDE S - ACIDIFICANTE - ÁCIDOS ORGÁNICOS [IMVAB_PAGINA3 | PDF]
A932: 1 | B932: Detalles: FELIGEN CRP - VACUNA FELINA - CALICIVIRUS, RINOTRAQUEITIS, PANLEUCOPENIA - FRASCO - 1 DOSIS [IMVAB_PAGINA4 | PDF]
A933: 2 | B933: Detalles: FELIGEN CRP/R - VACUNA FELINA + RABIA [IMVAB_PAGINA4 | PDF]
A934: 3 | B934: Detalles: FOKKAMEL EXTRA - NUTRICIONAL - AMINOÁCIDOS, VITAMINAS, PROBIÓTICOS - SACO - 25 KG [IMVAB_PAGINA4 | PDF]
A935: 4 | B935: Detalles: FOLREX PETS - CONDROPROTECTOR - QUITINA - FRASCO - 150 ML [IMVAB_PAGINA4 | PDF]
A936: 5 | B936: Detalles: FOLREX PETS - MISMA COMPOSICIÓN - VIALES - 30 ML [IMVAB_PAGINA4 | PDF]
A937: 6 | B937: Detalles: FOSFOSAN - MACROMINERALES - Ca, P, Mg, Cu, Se [IMVAB_PAGINA4 | PDF]
A938: 7 | B938: Detalles: FOSFOSAN - MISMA COMPOSICIÓN - 500 ML [IMVAB_PAGINA4 | PDF]
A939: 8 | B939: Detalles: FRA C12 DRY - PROMOTOR DE CRECIMIENTO - MONOLAURINA [IMVAB_PAGINA4 | PDF]
A940: 84–86. Detalles: HASLEY - SUPLEMENTO NUTRICIONAL - PROTEÍNAS, AMINOÁCIDOS, VITAMINAS (varias presentaciones) [IMVAB_PAGINA4 | PDF]
A941: 1 | B941: Detalles: HEPATONIC - HEPATOPROTECTOR - ÁCIDO GENABÍLICO, SORBITOL [IMVAB_PAGINA4 | PDF]
A942: 2 | B942: Detalles: HEXADENE SPHERULITES - ANTIMICÓTICO - CLORHEXIDINA [IMVAB_PAGINA4 | PDF]
A943: 3 | B943: Detalles: HISTAMIN - ANTIHISTAMÍNICO - DIFENHIDRAMINA, LIDOCAÍNA [IMVAB_PAGINA4 | PDF]
A944: 4 | B944: Detalles: IMIDOGAN - ANTIPARASITARIO HEMÁTICO - IMIDOCARB [IMVAB_PAGINA4 | PDF]
A945: 5 | B945: Detalles: IVENCILINA 800 - ANTIBIÓTICO - AMOXICILINA [IMVAB_PAGINA4 | PDF]
A946: 92–93. Detalles: KALSIS PETS - MINERALES - CALCIO, MAGNESIO [IMVAB_PAGINA4 | PDF]
A947: 94–95. Detalles: KARDIOLI PETS - MINERALES + EXTRACTOS [IMVAB_PAGINA4 | PDF]
...

Sheet Datos_Normalizados
A1: NOMBRE_PRODUCTO | B1: CATEGORÍA | C1: INGREDIENTES_COMPOSICIÓN | D1: PRESENTACIÓN | E1: CANTIDAD
A2: {=TRIM(IFERROR(INDEX(_xlfn.TEXTSPLIT(Hoja1!A1," - "),1),""))} -> ACID PAK 4 WAY WS 2X | B2: {=TRIM(IFERROR(INDEX(_xlfn.TEXTSPLIT(Hoja1!A1," - "),2),""))} -> ACIDIFICANTES AVICULTURA | C2: {=TRIM(IFERROR(_xlfn.LET(_xlpm.partes,_xlfn.TEXTSPLIT(Hoja1!A1," - "),_xlpm.n,COLUMNS(_xlpm.partes),IF(_xlpm.n>4,_xlfn.TEXTJOIN(", ",TRUE,INDEX(_xlpm.partes,_xlfn.SEQUENCE(1,_xlpm.n-4,3))),INDEX(_xlpm.partes,3))),""))} -> ÁCIDO CÍTRICO, ÁCIDO SÓRBICO, STREPTOCOCCUS FAECIUM, CITRATO DE SODIO, CLORETO DE SODIO, SULFATO DE MANGANESO, CLORETO DE POTASIO, DEXTROSA, STREPTOCOCCUS FAECIUM, LACTOBACILLUS ACIDOPHILUS, ASPERGILLUS NIGER, BACILLUS SUBTILIS, BETAGLUCAN | D2: {=TRIM(IFERROR(_xlfn.LET(_xlpm.partes,_xlfn.TEXTSPLIT(Hoja1!A1," - "),_xlpm.n,COLUMNS(_xlpm.partes),INDEX(_xlpm.partes,_xlpm.n-1)),""))} -> BOLSA | E2: {=TRIM(IFERROR(_xlfn.LET(_xlpm.partes,_xlfn.TEXTSPLIT(Hoja1!A1," - "),_xlpm.n,COLUMNS(_xlpm.partes),INDEX(_xlpm.partes,_xlpm.n)),""))} -> 1 KG
A3: {=TRIM(IFERROR(INDEX(_xlfn.TEXTSPLIT(Hoja1!A2," - "),1),""))} -> ACRILÁN | B3: {=TRIM(IFERROR(INDEX(_xlfn.TEXTSPLIT(Hoja1!A2," - "),2),""))} -> ANTISEPTICOS Y CICATRIZANTES | C3: {=TRIM(IFERROR(_xlfn.LET(_xlpm.partes,_xlfn.TEXTSPLIT(Hoja1!A2," - "),_xlpm.n,COLUMNS(_xlpm.partes),IF(_xlpm.n>4,_xlfn.TEXTJOIN(", ",TRUE,INDEX(_xlpm.partes,_xlfn.SEQUENCE(1,_xlpm.n-4,3))),INDEX(_xlpm.partes,3))),""))} -> ACRIFLAVINA | D3: {=TRIM(IFERROR(_xlfn.LET(_xlpm.partes,_xlfn.TEXTSPLIT(Hoja1!A2," - "),_xlpm.n,COLUMNS(_xlpm.partes),INDEX(_xlpm.partes,_xlpm.n-1)),""))} -> TUBO | E3: {=TRIM(IFERROR(_xlfn.LET(_xlpm.partes,_xlfn.TEXTSPLIT(Hoja1!A2," - "),_xlpm.n,COLUMNS(_xlpm.partes),INDEX(_xlpm.partes,_xlpm.n)),""))} -> 50 GR
A4: {=TRIM(IFERROR(INDEX(_xlfn.TEXTSPLIT(Hoja1!A3," - "),1),""))} -> AGRILAC PLUS | B4: {=TRIM(IFERROR(INDEX(_xlfn.TEXTSPLIT(Hoja1!A3," - "),2),""))} -> ALIMENTO MEDICADO GANADERIA | C4: {=TRIM(IFERROR(_xlfn.LET(_xlpm.partes,_xlfn.TEXTSPLIT(Hoja1!A3," - "),_xlpm.n,COLUMNS(_xlpm.partes),IF(_xlpm.n>4,_xlfn.TEXTJOIN(", ",TRUE,INDEX(_xlpm.partes,_xlfn.SEQUENCE(1,_xlpm.n-4,3))),INDEX(_xlpm.partes,3))),""))} -> PRODUCTOS LÁCTEOS, ACEITES VEGETALES, OXITETRACICLINA, SULFATO DE NEOMICINA, ACEITES ORGÁNICOS, PREMEZCLA VITAMINAS, PREMEZCLA MINERALES, BHT, SABORIZANTE VAINILLA | D4: {=TRIM(IFERROR(_xlfn.LET(_xlpm.partes,_xlfn.TEXTSPLIT(Hoja1!A3," - "),_xlpm.n,COLUMNS(_xlpm.partes),INDEX(_xlpm.partes,_xlpm.n-1)),""))} -> SACO | E4: {=TRIM(IFERROR(_xlfn.LET(_xlpm.partes,_xlfn.TEXTSPLIT(Hoja1!A3," - "),_xlpm.n,COLUMNS(_xlpm.partes),INDEX(_xlpm.partes,_xlpm.n)),""))} -> 20 KG
A5: {=TRIM(IFERROR(INDEX(_xlfn.TEXTSPLIT(Hoja1!A4," - "),1),""))} -> ALCON BROILER FINAL COSTA GRANJA | B5: {=TRIM(IFERROR(INDEX(_xlfn.TEXTSPLIT(Hoja1!A4," - "),2),""))} -> ALIMENTO BALANCEADO AVES | C5: {=TRIM(IFERROR(_xlfn.LET(_xlpm.partes,_xlfn.TEXTSPLIT(Hoja1!A4," - "),_xlpm.n,COLUMNS(_xlpm.partes),IF(_xlpm.n>4,_xlfn.TEXTJOIN(", ",TRUE,INDEX(_xlpm.partes,_xlfn.SEQUENCE(1,_xlpm.n-4,3))),INDEX(_xlpm.partes,3))),""))} -> SUBPRODUCTOS DE MAÍZ, SOYA Y TRIGO, ACEITE VEGETAL, AMINOÁCIDOS, PREMIX VITAMINICO MINERAL, ADITIVOS FUNCIONALES, CARBONATO DE CALCIO, HIDROLIZADO MARINO, FOSFATO CÁLCICO | D5: {=TRIM(IFERROR(_xlfn.LET(_xlpm.partes,_xlfn.TEXTSPLIT(Hoja1!A4," - "),_xlpm.n,COLUMNS(_xlpm.partes),INDEX(_xlpm.partes,_xlpm.n-1)),""))} -> SACO | E5: {=TRIM(IFERROR(_xlfn.LET(_xlpm.partes,_xlfn.TEXTSPLIT(Hoja1!A4," - "),_xlpm.n,COLUMNS(_xlpm.partes),INDEX(_xlpm.partes,_xlpm.n)),""))} -> 40 KG
A6: {=TRIM(IFERROR(INDEX(_xlfn.TEXTSPLIT(Hoja1!A5," - "),1),""))} -> ALCON BROILER FINAL SIERRA | B6: {=TRIM(IFERROR(INDEX(_xlfn.TEXTSPLIT(Hoja1!A5," - "),2),""))} -> ALIMENTO BALANCEADO AVES | C6: {=TRIM(IFERROR(_xlfn.LET(_xlpm.partes,_xlfn.TEXTSPLIT(Hoja1!A5," - "),_xlpm.n,COLUMNS(_xlpm.partes),IF(_xlpm.n>4,_xlfn.TEXTJOIN(", ",TRUE,INDEX(_xlpm.partes,_xlfn.SEQUENCE(1,_xlpm.n-4,3))),INDEX(_xlpm.partes,3))),""))} -> SUBPRODUCTOS DE MAÍZ, SOYA Y TRIGO, ACEITE VEGETAL, AMINOÁCIDOS, PREMIX VITAMINICO MINERAL, ADITIVOS FUNCIONALES, CARBONATO DE CALCIO, HIDROLIZADO MARINO, FOSFATO CÁLCICO | D6: {=TRIM(IFERROR(_xlfn.LET(_xlpm.partes,_xlfn.TEXTSPLIT(Hoja1!A5," - "),_xlpm.n,COLUMNS(_xlpm.partes),INDEX(_xlpm.partes,_xlpm.n-1)),""))} -> SACO | E6: {=TRIM(IFERROR(_xlfn.LET(_xlpm.partes,_xlfn.TEXTSPLIT(Hoja1!A5," - "),_xlpm.n,COLUMNS(_xlpm.partes),INDEX(_xlpm.partes,_xlpm.n)),""))} -> 40 KG
A7: {=TRIM(IFERROR(INDEX(_xlfn.TEXTSPLIT(Hoja1!A6," - "),1),""))} -> ALCON BROILER INICIAL COSTA GRANJA | B7: {=TRIM(IFERROR(INDEX(_xlfn.TEXTSPLIT(Hoja1!A6," - "),2),""))} -> ALIMENTO BALANCEADO AVES | C7: {=TRIM(IFERROR(_xlfn.LET(_xlpm.partes,_xlfn.TEXTSPLIT(Hoja1!A6," - "),_xlpm.n,COLUMNS(_xlpm.partes),IF(_xlpm.n>4,_xlfn.TEXTJOIN(", ",TRUE,INDEX(_xlpm.partes,_xlfn.SEQUENCE(1,_xlpm.n-4,3))),INDEX(_xlpm.partes,3))),""))} -> SUBPRODUCTOS DE MAÍZ, SOYA Y TRIGO, ACEITE VEGETAL, AMINOÁCIDOS, PREMIX VITAMINICO MINERAL, ADITIVOS FUNCIONALES, CARBONATO DE CALCIO, HIDROLIZADO MARINO, FOSFATO CÁLCICO | D7: {=TRIM(IFERROR(_xlfn.LET(_xlpm.partes,_xlfn.TEXTSPLIT(Hoja1!A6," - "),_xlpm.n,COLUMNS(_xlpm.partes),INDEX(_xlpm.partes,_xlpm.n-1)),""))} -> SACO | E7: {=TRIM(IFERROR(_xlfn.LET(_xlpm.partes,_xlfn.TEXTSPLIT(Hoja1!A6," - "),_xlpm.n,COLUMNS(_xlpm.partes),INDEX(_xlpm.partes,_xlpm.n)),""))} -> 40 KG
A8: {=TRIM(IFERROR(INDEX(_xlfn.TEXTSPLIT(Hoja1!A7," - "),1),""))} -> ALCON BROILER INICIAL SIERRA | B8: {=TRIM(IFERROR(INDEX(_xlfn.TEXTSPLIT(Hoja1!A7," - "),2),""))} -> ALIMENTO BALANCEADO AVES | C8: {=TRIM(IFERROR(_xlfn.LET(_xlpm.partes,_xlfn.TEXTSPLIT(Hoja1!A7," - "),_xlpm.n,COLUMNS(_xlpm.partes),IF(_xlpm.n>4,_xlfn.TEXTJOIN(", ",TRUE,INDEX(_xlpm.partes,_xlfn.SEQUENCE(1,_xlpm.n-4,3))),INDEX(_xlpm.partes,3))),""))} -> SUBPRODUCTOS DE MAÍZ, SOYA Y TRIGO, ACEITE VEGETAL, AMINOÁCIDOS, PREMIX VITAMINICO MINERAL, ADITIVOS FUNCIONALES, CARBONATO DE CALCIO, HIDROLIZADO MARINO, FOSFATO CÁLCICO | D8: {=TRIM(IFERROR(_xlfn.LET(_xlpm.partes,_xlfn.TEXTSPLIT(Hoja1!A7," - "),_xlpm.n,COLUMNS(_xlpm.partes),INDEX(_xlpm.partes,_xlpm.n-1)),""))} -> SACO | E8: {=TRIM(IFERROR(_xlfn.LET(_xlpm.partes,_xlfn.TEXTSPLIT(Hoja1!A7," - "),_xlpm.n,COLUMNS(_xlpm.partes),INDEX(_xlpm.partes,_xlpm.n)),""))} -> 40 KG
A9: {=TRIM(IFERROR(INDEX(_xlfn.TEXTSPLIT(Hoja1!A8," - "),1),""))} -> ALCON BROILER PREINICIAL COSTA GRANJA | B9: {=TRIM(IFERROR(INDEX(_xlfn.TEXTSPLIT(Hoja1!A8," - "),2),""))} -> ALIMENTO BALANCEADO AVES | C9: {=TRIM(IFERROR(_xlfn.LET(_xlpm.partes,_xlfn.TEXTSPLIT(Hoja1!A8," - "),_xlpm.n,COLUMNS(_xlpm.partes),IF(_xlpm.n>4,_xlfn.TEXTJOIN(", ",TRUE,INDEX(_xlpm.partes,_xlfn.SEQUENCE(1,_xlpm.n-4,3))),INDEX(_xlpm.partes,3))),""))} -> SUBPRODUCTOS DE MAÍZ, SOYA Y TRIGO, ACEITE VEGETAL, AMINOÁCIDOS, PREMIX VITAMINICO MINERAL, ADITIVOS FUNCIONALES, CARBONATO DE CALCIO, HIDROLIZADO MARINO | D9: {=TRIM(IFERROR(_xlfn.LET(_xlpm.partes,_xlfn.TEXTSPLIT(Hoja1!A8," - "),_xlpm.n,COLUMNS(_xlpm.partes),INDEX(_xlpm.partes,_xlpm.n-1)),""))} -> SACO | E9: {=TRIM(IFERROR(_xlfn.LET(_xlpm.partes,_xlfn.TEXTSPLIT(Hoja1!A8," - "),_xlpm.n,COLUMNS(_xlpm.partes),INDEX(_xlpm.partes,_xlpm.n)),""))} -> 40 KG
A10: {=TRIM(IFERROR(INDEX(_xlfn.TEXTSPLIT(Hoja1!A9," - "),1),""))} -> ALCON CERDA GESTACIÓN | B10: {=TRIM(IFERROR(INDEX(_xlfn.TEXTSPLIT(Hoja1!A9," - "),2),""))} -> ALIMENTO MEDICADO GANADERIA | C10: {=TRIM(IFERROR(_xlfn.LET(_xlpm.partes,_xlfn.TEXTSPLIT(Hoja1!A9," - "),_xlpm.n,COLUMNS(_xlpm.partes),IF(_xlpm.n>4,_xlfn.TEXTJOIN(", ",TRUE,INDEX(_xlpm.partes,_xlfn.SEQUENCE(1,_xlpm.n-4,3))),INDEX(_xlpm.partes,3))),""))} -> SUBPRODUCTOS DE TRIGO, MAÍZ Y SOYA, HARINAS DE AFRECHO, CARBONATO CALCIO, BICARBONATO DE SODIO, AMINOÁCIDOS, ADITIVOS FUNCIONALES, ACIDIFICANTE, PREMIX VITAMÍNICO MINERAL, CLORURO DE COLINA Y SODIO, PROMOTORES DE CRECIMIENTO, ACEITE VEGETAL | D10: {=TRIM(IFERROR(_xlfn.LET(_xlpm.partes,_xlfn.TEXTSPLIT(Hoja1!A9," - "),_xlpm.n,COLUMNS(_xlpm.partes),INDEX(_xlpm.partes,_xlpm.n-1)),""))} -> SACO | E10: {=TRIM(IFERROR(_xlfn.LET(_xlpm.partes,_xlfn.TEXTSPLIT(Hoja1!A9," - "),_xlpm.n,COLUMNS(_xlpm.partes),INDEX(_xlpm.partes,_xlpm.n)),""))} -> 40 KG
A11: {=TRIM(IFERROR(INDEX(_xlfn.TEXTSPLIT(Hoja1!A10," - "),1),""))} -> ALCON CERDA LACTANTE | B11: {=TRIM(IFERROR(INDEX(_xlfn.TEXTSPLIT(Hoja1!A10," - "),2),""))} -> ALIMENTO MEDICADO GANADERIA | C11: {=TRIM(IFERROR(_xlfn.LET(_xlpm.partes,_xlfn.TEXTSPLIT(Hoja1!A10," - "),_xlpm.n,COLUMNS(_xlpm.partes),IF(_xlpm.n>4,_xlfn.TEXTJOIN(", ",TRUE,INDEX(_xlpm.partes,_xlfn.SEQUENCE(1,_xlpm.n-4,3))),INDEX(_xlpm.partes,3))),""))} -> SUBPRODUCTOS DE MAÍZ, TRIGO Y SOYA, HARINAS DE AFRECHO, MELAZA, ACEITE VEGETAL, BICARBONATO DE SODIO, AMINOÁCIDOS, ACIDIFICANTE, ADITIVOS FUNCIONALES, SAL, PREMIX VITAMÍNICO MINERAL, CLORURO DE COLINA, ANTIOXIDANTE, ENZIMA, PROMOTORES DE CRECIMIENTO | D11: {=TRIM(IFERROR(_xlfn.LET(_xlpm.partes,_xlfn.TEXTSPLIT(Hoja1!A10," - "),_xlpm.n,COLUMNS(_xlpm.partes),INDEX(_xlpm.partes,_xlpm.n-1)),""))} -> SACO | E11: {=TRIM(IFERROR(_xlfn.LET(_xlpm.partes,_xlfn.TEXTSPLIT(Hoja1!A10," - "),_xlpm.n,COLUMNS(_xlpm.partes),INDEX(_xlpm.partes,_xlpm.n)),""))} -> 40 KG
A12: {=TRIM(IFERROR(INDEX(_xlfn.TEXTSPLIT(Hoja1!A11," - "),1),""))} -> ALCON CERDO ACABADO | B12: {=TRIM(IFERROR(INDEX(_xlfn.TEXTSPLIT(Hoja1!A11," - "),2),""))} -> ALIMENTO MEDICADO GANADERIA | C12: {=TRIM(IFERROR(_xlfn.LET(_xlpm.partes,_xlfn.TEXTSPLIT(Hoja1!A11," - "),_xlpm.n,COLUMNS(_xlpm.partes),IF(_xlpm.n>4,_xlfn.TEXTJOIN(", ",TRUE,INDEX(_xlpm.partes,_xlfn.SEQUENCE(1,_xlpm.n-4,3))),INDEX(_xlpm.partes,3))),""))} -> SUBPRODUCTOS DE MAÍZ, TRIGO Y SOYA, HARINAS DE AFRECHO, ACEITE VEGETAL, BICARBONATO DE SODIO, ACIDIFICANTE, ADITIVOS FUNCIONALES, PREMIX VITAMÍNICO MINERAL, CLORURO DE SODIO Y COLINA, ANTIOXIDANTES, ENZIMAS, PROMOTORES DE CRECIMIENTO | D12: {=TRIM(IFERROR(_xlfn.LET(_xlpm.partes,_xlfn.TEXTSPLIT(Hoja1!A11," - "),_xlpm.n,COLUMNS(_xlpm.partes),INDEX(_xlpm.partes,_xlpm.n-1)),""))} -> SACO | E12: {=TRIM(IFERROR(_xlfn.LET(_xlpm.partes,_xlfn.TEXTSPLIT(Hoja1!A11," - "),_xlpm.n,COLUMNS(_xlpm.partes),INDEX(_xlpm.partes,_xlpm.n)),""))} -> 40 KG
A13: {=TRIM(IFERROR(INDEX(_xlfn.TEXTSPLIT(Hoja1!A12," - "),1),""))} -> ALCON CERDO CRECIMIENTO | B13: {=TRIM(IFERROR(INDEX(_xlfn.TEXTSPLIT(Hoja1!A12," - "),2),""))} -> ALIMENTO MEDICADO GANADERIA | C13: {=TRIM(IFERROR(_xlfn.LET(_xlpm.partes,_xlfn.TEXTSPLIT(Hoja1!A12," - "),_xlpm.n,COLUMNS(_xlpm.partes),IF(_xlpm.n>4,_xlfn.TEXTJOIN(", ",TRUE,INDEX(_xlpm.partes,_xlfn.SEQUENCE(1,_xlpm.n-4,3))),INDEX(_xlpm.partes,3))),""))} -> SUBPRODUCTOS DE MAÍZ, TRIGO Y SOYA, HARINAS DE AFRECHO, ACEITE VEGETAL, BICARBONATO DE SODIO, ACIDIFICANTE, AMINOÁCIDOS, ADITIVOS FUNCIONALES, PREMIX VITAMÍNICO MINERAL, CLORURO DE COLINA Y SODIO, ANTIOXIDANTES, ENZIMAS, PROMOTORES DE CRECIMIENTO | D13: {=TRIM(IFERROR(_xlfn.LET(_xlpm.partes,_xlfn.TEXTSPLIT(Hoja1!A12," - "),_xlpm.n,COLUMNS(_xlpm.partes),INDEX(_xlpm.partes,_xlpm.n-1)),""))} -> SACO | E13: {=TRIM(IFERROR(_xlfn.LET(_xlpm.partes,_xlfn.TEXTSPLIT(Hoja1!A12," - "),_xlpm.n,COLUMNS(_xlpm.partes),INDEX(_xlpm.partes,_xlpm.n)),""))} -> 40 KG
... A1512: {=TRIM(IFERROR(INDEX(_xlfn.TEXTSPLIT(Hoja1!A1511," - "),1),""))} -> 125,"RIMADYL | B1512: {=TRIM(IFERROR(INDEX(_xlfn.TEXTSPLIT(Hoja1!A1511," - "),2),""))} -> ANTIINFLAMATORIO | C1512: {=TRIM(IFERROR(_xlfn.LET(_xlpm.partes,_xlfn.TEXTSPLIT(Hoja1!A1511," - "),_xlpm.n,COLUMNS(_xlpm.partes),IF(_xlpm.n>4,_xlfn.TEXTJOIN(", ",TRUE,INDEX(_xlpm.partes,_xlfn.SEQUENCE(1,_xlpm.n-4,3))),INDEX(_xlpm.partes,3))),""))} -> CARPROFENO | D1512: {=TRIM(IFERROR(_xlfn.LET(_xlpm.partes,_xlfn.TEXTSPLIT(Hoja1!A1511," - "),_xlpm.n,COLUMNS(_xlpm.partes),INDEX(_xlpm.partes,_xlpm.n-1)),""))} -> TABLETAS | E1512: {=TRIM(IFERROR(_xlfn.LET(_xlpm.partes,_xlfn.TEXTSPLIT(Hoja1!A1511," - "),_xlpm.n,COLUMNS(_xlpm.partes),INDEX(_xlpm.partes,_xlpm.n)),""))} -> 100 MG"
